<?xml version="1.0" ?>
<!-- =================================================================================== -->
<!-- |    This document was autogenerated by xacro from src/igvc_test_description/urdf/robots/test_robot.urdf.xacro | -->
<!-- |    EDITING THIS FILE BY HAND IS NOT RECOMMENDED                                 | -->
<!-- =================================================================================== -->
<robot name="igvc_test_robot">
  <ros2_control name="igvc_test_bot" type="system">
    <hardware>
      <plugin>grr_hardware/IsaacDriveHardware</plugin>
    </hardware>
    <joint name="right_wheel_joint">
      <command_interface name="velocity">
        <param name="min">-1</param>
        <param name="max">1</param>
      </command_interface>
      <state_interface name="position"/>
      <state_interface name="velocity"/>
    </joint>
    <joint name="left_wheel_joint">
      <command_interface name="velocity">
        <param name="min">-1</param>
        <param name="max">1</param>
      </command_interface>
      <state_interface name="position"/>
      <state_interface name="velocity"/>
    </joint>
  </ros2_control>
  <material name="zed_mat">
    <color rgba="0.8 0.8 0.8 1.0"/>
  </material>
  <material name="zedm_mat">
    <color rgba="0 0 0 1.0"/>
  </material>
  <material name="zed2_mat">
    <color rgba="0.25 0.25 0.25 1.0"/>
  </material>
  <material name="zed2i_mat">
    <color rgba="0.25 0.25 0.25 1.0"/>
  </material>
  <material name="zedx_mat">
    <color rgba="0.25 0.25 0.25 1.0"/>
  </material>
  <material name="zedxm_mat">
    <color rgba="0.25 0.25 0.25 1.0"/>
  </material>
  <material name="zedxhdr_mat">
    <color rgba="0.25 0.25 0.25 1.0"/>
  </material>
  <material name="zedxhdrmini_mat">
    <color rgba="0.25 0.25 0.25 1.0"/>
  </material>
  <material name="zedxhdrmax_mat">
    <color rgba="0.25 0.25 0.25 1.0"/>
  </material>
  <material name="virtual_mat">
    <color rgba="0.25 0.25 0.25 1.0"/>
  </material>
  <material name="zedxonegs_mat">
    <color rgba="0.25 0.25 0.25 1.0"/>
  </material>
  <material name="zedxone4k_mat">
    <color rgba="0.25 0.25 0.25 1.0"/>
  </material>
  <material name="zedxonehdr_mat">
    <color rgba="0.25 0.25 0.25 1.0"/>
  </material>
  <joint name="caster_raceway_joint" type="continuous">
    <origin rpy="0. 0. 0." xyz="0.0011449 -0.3728886 -0.0307033"/>
    <parent link="chassis_link"/>
    <child link="caster_raceway_link"/>
    <axis xyz="0. 0. 1."/>
  </joint>
  <joint name="caster_wheel_joint" type="continuous">
    <origin rpy="-1.5707961 -0.0862496 2.4779847" xyz="-0.0452015 0.004609 -0.1223279"/>
    <parent link="caster_raceway_link"/>
    <child link="caster_wheel_link"/>
    <axis xyz="0. 0. 1."/>
  </joint>
  <joint name="left_wheel_joint" type="continuous">
    <origin rpy="0. 0. 0." xyz="0.2844359 0.1500906 -0.1274171"/>
    <parent link="chassis_link"/>
    <child link="left_wheel_link"/>
    <axis xyz="1. 0. 0."/>
  </joint>
  <joint name="right_wheel_joint" type="continuous">
    <origin rpy="0. 0. 0." xyz="-0.2918941 0.1492591 -0.1296445"/>
    <parent link="chassis_link"/>
    <child link="right_wheel_link"/>
    <axis xyz="1. 0. 0."/>
  </joint>
  <joint name="rootJoint" type="fixed">
    <origin rpy="0. 0. -0." xyz="0. 0. 0."/>
    <parent link="base_link"/>
    <child link="chassis_link"/>
  </joint>
  <link name="base_link"/>
  <link name="caster_raceway_link">
    <inertial>
      <origin rpy="0. 0. 0." xyz="-0.0118137 0.0087306 -0.0584325"/>
      <mass value="0.2597675"/>
      <inertia ixx="0.0003673" ixy="0.0001647" ixz="0." iyy="0.0004492" iyz="-0." izz="0.0006678"/>
    </inertial>
    <visual>
      <origin rpy="0. 0. -0.663608" xyz="-0.0011449 0.0003886 -0.0088217"/>
      <geometry>
        <mesh filename="package://igvc_test_description/meshes/caster_raceway_link_Part_2_Part_2.obj" scale="1. 1. 1."/>
      </geometry>
    </visual>
    <collision>
      <origin rpy="0. 0. -0.663608" xyz="-0.0011449 0.0003886 -0.0088217"/>
      <geometry>
        <mesh filename="package://igvc_test_description/meshes/caster_raceway_link_Part_2_Part_2.obj" scale="1. 1. 1."/>
      </geometry>
    </collision>
  </link>
  <link name="caster_wheel_link">
    <inertial>
      <origin rpy="0. 0. 0." xyz="-0. -0. -0.0238125"/>
      <mass value="1.0005643"/>
      <inertia ixx="0.0017247" ixy="-0." ixz="0." iyy="0.0030953" iyz="-0." izz="0.0017247"/>
    </inertial>
    <visual>
      <origin rpy="-1.5707965 -0.0000001 0. " xyz="0.0373062 0.1135063 -0.0238125"/>
      <geometry>
        <mesh filename="package://igvc_test_description/meshes/caster_wheel_link__in_Caster__in_Caster.obj" scale="1. 1. 1."/>
      </geometry>
    </visual>
    <collision>
      <origin rpy="-1.5707965 -0.0000001 0. " xyz="0.0373062 0.1135063 -0.0238125"/>
      <geometry>
        <mesh filename="package://igvc_test_description/meshes/caster_wheel_link__in_Caster__in_Caster.obj" scale="1. 1. 1."/>
      </geometry>
    </collision>
  </link>
  <link name="left_wheel_link">
    <inertial>
      <origin rpy="0. 0. 0." xyz="-0.0010859 -0.0000906 -0.0010079"/>
      <mass value="2.1118586"/>
      <inertia ixx="0.0059185" ixy="-0." ixz="-0." iyy="0.0086441" iyz="0.0022525" izz="0.00778"/>
    </inertial>
    <visual>
      <origin rpy="0. 0.8801533 1.5707964" xyz="-0.0010859 -0.0000906 -0.0010079"/>
      <geometry>
        <mesh filename="package://igvc_test_description/meshes/left_wheel_link__in_Wheel_Stand_In_01__in_Wheel_Stand_In.obj" scale="1. 1. 1."/>
      </geometry>
    </visual>
    <collision>
      <origin rpy="0. 0.8801533 1.5707964" xyz="-0.0010859 -0.0000906 -0.0010079"/>
      <geometry>
        <mesh filename="package://igvc_test_description/meshes/left_wheel_link__in_Wheel_Stand_In_01__in_Wheel_Stand_In.obj" scale="1. 1. 1."/>
      </geometry>
    </collision>
  </link>
  <link name="right_wheel_link">
    <inertial>
      <origin rpy="0. 0. 0." xyz="0.0085441 0.0007409 0.0012195"/>
      <mass value="2.1118586"/>
      <inertia ixx="0.0059185" ixy="-0." ixz="0." iyy="0.0059185" iyz="-0." izz="0.0105056"/>
    </inertial>
    <visual>
      <origin rpy="3.1415927 0. -1.5707964" xyz="0.0085441 0.0007409 0.0012195"/>
      <geometry>
        <mesh filename="package://igvc_test_description/meshes/right_wheel_link__in_Wheel_Stand_In_01__in_Wheel_Stand_In.obj" scale="1. 1. 1."/>
      </geometry>
    </visual>
    <collision>
      <origin rpy="3.1415927 0. -1.5707964" xyz="0.0085441 0.0007409 0.0012195"/>
      <geometry>
        <mesh filename="package://igvc_test_description/meshes/right_wheel_link__in_Wheel_Stand_In_01__in_Wheel_Stand_In.obj" scale="1. 1. 1."/>
      </geometry>
    </collision>
  </link>
  <link name="chassis_link">
    <inertial>
      <origin rpy="0. 0. 0." xyz="0. 0. 0."/>
      <mass value="20."/>
      <inertia ixx="0.001" ixy="0." ixz="0." iyy="0.001" iyz="0." izz="0.001"/>
    </inertial>
    <visual>
      <origin rpy="0. 0. 0." xyz="0. 0. 0."/>
      <geometry>
        <mesh filename="package://igvc_test_description/meshes/_FE2CBA3_2B86_49A6_86C6_46C335366A6A.obj" scale="1. 1. 1."/>
      </geometry>
    </visual>
    <collision>
      <origin rpy="0. 0. 0." xyz="0. 0. 0."/>
      <geometry>
        <mesh filename="package://igvc_test_description/meshes/_FE2CBA3_2B86_49A6_86C6_46C335366A6A.obj" scale="1. 1. 1."/>
      </geometry>
    </collision>
  </link>
  <!-- Camera mounting point (the threaded screw hole in the bottom) -->
  <link name="left_zed_camera_x_camera_link"/>
  <!-- Camera Center -->
  <link name="left_zed_camera_x_camera_center">
    <visual>
      <origin rpy="0 0 0" xyz="0.0 0 -0.016"/>
      <geometry>
        <mesh filename="package://zed_description/meshes/zedx.stl"/>
      </geometry>
      <material name="zedx_mat"/>
    </visual>
    <collision>
      <origin rpy="0 0 0" xyz="0.0 0 -0.016"/>
      <geometry>
        <mesh filename="package://zed_description/meshes/zedx.stl"/>
      </geometry>
    </collision>
  </link>
  <joint name="left_zed_camera_x_camera_center_joint" type="fixed">
    <parent link="left_zed_camera_x_camera_link"/>
    <child link="left_zed_camera_x_camera_center"/>
    <origin rpy="0 0.0 0" xyz="0 0 0.016"/>
  </joint>
  <!-- Left Camera -->
  <link name="left_zed_camera_x_left_camera_frame">
  </link>
  <joint name="left_zed_camera_x_left_camera_joint" type="fixed">
    <parent link="left_zed_camera_x_camera_center"/>
    <child link="left_zed_camera_x_left_camera_frame"/>
    <origin rpy="0 0 0" xyz="-0.01 0.06 0"/>
  </joint>
  <link name="left_zed_camera_x_left_camera_optical_frame"/>
  <joint name="left_zed_camera_x_left_camera_optical_joint" type="fixed">
    <origin rpy="-1.5707963267948966 0.0 -1.5707963267948966" xyz="0 0 0"/>
    <parent link="left_zed_camera_x_left_camera_frame"/>
    <child link="left_zed_camera_x_left_camera_optical_frame"/>
  </joint>
  <!-- Right Camera -->
  <link name="left_zed_camera_x_right_camera_frame">
  </link>
  <joint name="left_zed_camera_x_right_camera_joint" type="fixed">
    <parent link="left_zed_camera_x_camera_center"/>
    <child link="left_zed_camera_x_right_camera_frame"/>
    <origin rpy="0 0 0" xyz="-0.01 -0.06 0"/>
  </joint>
  <link name="left_zed_camera_x_right_camera_optical_frame"/>
  <joint name="left_zed_camera_x_right_camera_optical_joint" type="fixed">
    <origin rpy="-1.5707963267948966 0.0 -1.5707963267948966" xyz="0 0 0"/>
    <parent link="left_zed_camera_x_right_camera_frame"/>
    <child link="left_zed_camera_x_right_camera_optical_frame"/>
  </joint>
  <link name="left_zed_camera_x_gnss_link"/>
  <joint name="left_zed_camera_x_gnss_joint" type="fixed">
    <parent link="left_zed_camera_x_camera_link"/>
    <child link="left_zed_camera_x_gnss_link"/>
    <gnss_origin rpy="0 0 0" xyz="0 0 0"/>
  </joint>
  <joint name="left_zed_camera_x_joint" type="fixed">
    <parent link="chassis_link"/>
    <child link="left_zed_camera_x_camera_link"/>
    <origin rpy="0 0 0" xyz="0.2 -0.1 1.57"/>
  </joint>
  <!-- Camera mounting point (the threaded screw hole in the bottom) -->
  <link name="front_zed_camera_x_camera_link"/>
  <!-- Camera Center -->
  <link name="front_zed_camera_x_camera_center">
    <visual>
      <origin rpy="0 0 0" xyz="0.0 0 -0.016"/>
      <geometry>
        <mesh filename="package://zed_description/meshes/zedx.stl"/>
      </geometry>
      <material name="zedx_mat"/>
    </visual>
    <collision>
      <origin rpy="0 0 0" xyz="0.0 0 -0.016"/>
      <geometry>
        <mesh filename="package://zed_description/meshes/zedx.stl"/>
      </geometry>
    </collision>
  </link>
  <joint name="front_zed_camera_x_camera_center_joint" type="fixed">
    <parent link="front_zed_camera_x_camera_link"/>
    <child link="front_zed_camera_x_camera_center"/>
    <origin rpy="0 0.0 0" xyz="0 0 0.016"/>
  </joint>
  <!-- Left Camera -->
  <link name="front_zed_camera_x_left_camera_frame">
  </link>
  <joint name="front_zed_camera_x_left_camera_joint" type="fixed">
    <parent link="front_zed_camera_x_camera_center"/>
    <child link="front_zed_camera_x_left_camera_frame"/>
    <origin rpy="0 0 0" xyz="-0.01 0.06 0"/>
  </joint>
  <link name="front_zed_camera_x_left_camera_optical_frame"/>
  <joint name="front_zed_camera_x_left_camera_optical_joint" type="fixed">
    <origin rpy="-1.5707963267948966 0.0 -1.5707963267948966" xyz="0 0 0"/>
    <parent link="front_zed_camera_x_left_camera_frame"/>
    <child link="front_zed_camera_x_left_camera_optical_frame"/>
  </joint>
  <!-- Right Camera -->
  <link name="front_zed_camera_x_right_camera_frame">
  </link>
  <joint name="front_zed_camera_x_right_camera_joint" type="fixed">
    <parent link="front_zed_camera_x_camera_center"/>
    <child link="front_zed_camera_x_right_camera_frame"/>
    <origin rpy="0 0 0" xyz="-0.01 -0.06 0"/>
  </joint>
  <link name="front_zed_camera_x_right_camera_optical_frame"/>
  <joint name="front_zed_camera_x_right_camera_optical_joint" type="fixed">
    <origin rpy="-1.5707963267948966 0.0 -1.5707963267948966" xyz="0 0 0"/>
    <parent link="front_zed_camera_x_right_camera_frame"/>
    <child link="front_zed_camera_x_right_camera_optical_frame"/>
  </joint>
  <link name="front_zed_camera_x_gnss_link"/>
  <joint name="front_zed_camera_x_gnss_joint" type="fixed">
    <parent link="front_zed_camera_x_camera_link"/>
    <child link="front_zed_camera_x_gnss_link"/>
    <gnss_origin rpy="0 0 0" xyz="0 0 0"/>
  </joint>
  <joint name="front_zed_camera_x_joint" type="fixed">
    <parent link="chassis_link"/>
    <child link="front_zed_camera_x_camera_link"/>
    <origin rpy="0 0 0" xyz="0.2 0 0"/>
  </joint>
  <!-- Camera mounting point (the threaded screw hole in the bottom) -->
  <link name="right_zed_camera_x_camera_link"/>
  <!-- Camera Center -->
  <link name="right_zed_camera_x_camera_center">
    <visual>
      <origin rpy="0 0 0" xyz="0.0 0 -0.016"/>
      <geometry>
        <mesh filename="package://zed_description/meshes/zedx.stl"/>
      </geometry>
      <material name="zedx_mat"/>
    </visual>
    <collision>
      <origin rpy="0 0 0" xyz="0.0 0 -0.016"/>
      <geometry>
        <mesh filename="package://zed_description/meshes/zedx.stl"/>
      </geometry>
    </collision>
  </link>
  <joint name="right_zed_camera_x_camera_center_joint" type="fixed">
    <parent link="right_zed_camera_x_camera_link"/>
    <child link="right_zed_camera_x_camera_center"/>
    <origin rpy="0 0.0 0" xyz="0 0 0.016"/>
  </joint>
  <!-- Left Camera -->
  <link name="right_zed_camera_x_left_camera_frame">
  </link>
  <joint name="right_zed_camera_x_left_camera_joint" type="fixed">
    <parent link="right_zed_camera_x_camera_center"/>
    <child link="right_zed_camera_x_left_camera_frame"/>
    <origin rpy="0 0 0" xyz="-0.01 0.06 0"/>
  </joint>
  <link name="right_zed_camera_x_left_camera_optical_frame"/>
  <joint name="right_zed_camera_x_left_camera_optical_joint" type="fixed">
    <origin rpy="-1.5707963267948966 0.0 -1.5707963267948966" xyz="0 0 0"/>
    <parent link="right_zed_camera_x_left_camera_frame"/>
    <child link="right_zed_camera_x_left_camera_optical_frame"/>
  </joint>
  <!-- Right Camera -->
  <link name="right_zed_camera_x_right_camera_frame">
  </link>
  <joint name="right_zed_camera_x_right_camera_joint" type="fixed">
    <parent link="right_zed_camera_x_camera_center"/>
    <child link="right_zed_camera_x_right_camera_frame"/>
    <origin rpy="0 0 0" xyz="-0.01 -0.06 0"/>
  </joint>
  <link name="right_zed_camera_x_right_camera_optical_frame"/>
  <joint name="right_zed_camera_x_right_camera_optical_joint" type="fixed">
    <origin rpy="-1.5707963267948966 0.0 -1.5707963267948966" xyz="0 0 0"/>
    <parent link="right_zed_camera_x_right_camera_frame"/>
    <child link="right_zed_camera_x_right_camera_optical_frame"/>
  </joint>
  <link name="right_zed_camera_x_gnss_link"/>
  <joint name="right_zed_camera_x_gnss_joint" type="fixed">
    <parent link="right_zed_camera_x_camera_link"/>
    <child link="right_zed_camera_x_gnss_link"/>
    <gnss_origin rpy="0 0 0" xyz="0 0 0"/>
  </joint>
  <joint name="right_zed_camera_x_joint" type="fixed">
    <parent link="chassis_link"/>
    <child link="right_zed_camera_x_camera_link"/>
    <origin rpy="0 0 0" xyz="0.2 0.1 -1.57"/>
  </joint>
</robot>
